#VRML_SIM R2023b utf8

EXTERNPROTO "https://raw.githubusercontent.com/cyberbotics/webots/R2023b/projects/appearances/protos/Asphalt.proto"
EXTERNPROTO "https://raw.githubusercontent.com/cyberbotics/webots/R2023b/projects/objects/backgrounds/protos/TexturedBackground.proto"
EXTERNPROTO "https://raw.githubusercontent.com/cyberbotics/webots/R2023b/projects/objects/backgrounds/protos/TexturedBackgroundLight.proto"
EXTERNPROTO "https://raw.githubusercontent.com/cyberbotics/webots/R2023b/projects/objects/floors/protos/UnevenTerrain.proto"

WorldInfo {
}
Viewpoint {
  orientation 0.15777712971554309 0.19752769919109775 -0.9675170207241812 1.380268275942312
  position 4.458960654197539 3.9853222753362805 5.578586006413582
}
TexturedBackground {
}
TexturedBackgroundLight {
}
Robot {
  translation 5.878509281119898 -0.029680770787529502 3.659854873624364
  rotation 0.8182452095093097 -0.5737191771350969 0.03634670414897173 0.07931776219115257
  children [
    InertialUnit {
    }
    DEF torso Shape {
      appearance PBRAppearance {
        baseColor 0.6 0.6 1
        metalness 0
      }
      geometry Box {
        size 1 1 0.2
      }
    }
    DEF wheel HingeJoint {
      jointParameters HingeJointParameters {
        position 32.79953390430023
        axis 0 1 0
        anchor -0.3 -0.577883 -0.0631591
      }
      device [
        RotationalMotor {
          name "motor1"
        }
      ]
      endPoint Solid {
        translation -0.3 -0.577883 -0.0631591
        rotation 0.6433407166831758 -0.5496385654896822 -0.5329260451357408 4.31322882093286
        children [
          DEF wheel_body Shape {
            appearance Asphalt {
            }
            geometry Cylinder {
              height 0.2
              radius 0.18
            }
          }
        ]
        boundingObject USE wheel_body
        physics DEF phy1 Physics {
          mass 1
        }
        linearVelocity -3.6058038628317128e-06 -4.707068415558792e-06 -5.469138706075664e-07
        angularVelocity 3.599350677824665e-09 -1.3224086610746634e-06 3.776892799954538e-07
      }
    }
    DEF wheel HingeJoint {
      jointParameters HingeJointParameters {
        position 32.7963165201994
        axis 0 1 0
        anchor 0.3 -0.577883 -0.0631591
      }
      device [
        RotationalMotor {
          name "motor2"
        }
      ]
      endPoint Solid {
        translation 0.3 -0.577883 -0.0631591
        rotation 0.6445753523809926 -0.5488924822182508 -0.5322026475574942 4.314996019714748
        children [
          DEF wheel_body Shape {
            appearance Asphalt {
            }
            geometry Cylinder {
              height 0.2
              radius 0.18
            }
          }
        ]
        name "solid(1)"
        boundingObject USE wheel_body
        physics DEF phy1 Physics {
          mass 1
        }
        linearVelocity -3.563613567304283e-06 -4.450766757690518e-06 -3.8801024851409256e-07
        angularVelocity 2.2988372963628192e-10 -1.27844708794779e-06 3.8024167286643397e-07
      }
    }
    DEF wheel HingeJoint {
      jointParameters HingeJointParameters {
        position 32.798986622565735
        axis 0 1 0
        anchor 0.3 0.577883 -0.0631591
      }
      device [
        RotationalMotor {
          name "motor3"
        }
      ]
      endPoint Solid {
        translation 0.3 0.577883 -0.0631591
        rotation 0.6435507460576151 -0.5495118183727747 -0.5328031519401267 4.31352959340018
        children [
          DEF wheel_body Shape {
            appearance Asphalt {
            }
            geometry Cylinder {
              height 0.2
              radius 0.18
            }
          }
        ]
        name "solid(2)"
        boundingObject USE wheel_body
        physics DEF phy1 Physics {
          mass 1
        }
        linearVelocity -4.1818157699362605e-06 -4.5854442956616e-06 -5.013701112375171e-07
        angularVelocity -3.61404963724655e-08 -5.969091484933805e-07 4.1940695482055966e-07
      }
    }
    DEF wheel HingeJoint {
      jointParameters HingeJointParameters {
        position 32.79985497869605
        axis 0 1 0
        anchor -0.3 0.577883 -0.0631591
      }
      device [
        RotationalMotor {
          name "motor4"
        }
      ]
      endPoint Solid {
        translation -0.3 0.577883 -0.0631591
        rotation 0.6432174954843112 -0.5497128933379829 -0.5329981129430701 4.313052334129534
        children [
          DEF wheel_body Shape {
            appearance Asphalt {
            }
            geometry Cylinder {
              height 0.2
              radius 0.18
            }
          }
        ]
        name "solid(3)"
        boundingObject USE wheel_body
        physics DEF phy1 Physics {
          mass 1
        }
        linearVelocity -4.13057924077087e-06 -4.742690219572409e-06 -4.543892000583542e-07
        angularVelocity -7.646296135654791e-09 -1.3496565022193226e-06 3.7535520178915413e-07
      }
    }
  ]
  boundingObject USE torso
  physics USE phy1
  controller "my_controller"
  linearVelocity -3.875872416457149e-06 -4.62208181122925e-06 -5.033163397456518e-07
  angularVelocity -1.135784613579995e-08 -1.1572351109807725e-07 4.5536761695724635e-07
}
UnevenTerrain {
}
